Workbook

Sheet Como usar
A1: Fluxo de Caixa Rural — 12 meses
A2: Coleção Gestão no Campo • Instruções de uso
B4: Legenda de cores:
B5: Amarelo claro | C5: Células para você preencher (digitação livre ou lista suspensa).
B6: Cinza claro | C6: Fórmulas automáticas. Ficam protegidas para evitar que sejam apagadas por engano.
B7: Verde claro | C7: Linhas de total e resultados principais.
B9: Passo a passo
B10: Passo 1 | C10: Aba Config: informe o nome da propriedade, o primeiro mês do controle (qualquer data do mês serve; ex.: 01/01/2026) e o saldo em caixa/banco no início desse mês.
B11: Passo 2 | C11: Ainda na Config: revise as categorias de ENTRADAS e SAÍDAS. Você pode renomear, excluir ou incluir categorias nas linhas livres — elas aparecem automaticamente nas demais abas.
B12: Passo 3 | C12: Aba Previsto: digite quanto você espera receber e gastar em cada categoria, mês a mês (o seu orçamento).
B13: Passo 4 | C13: Aba Lançamentos: registre cada entrada ou saída REALIZADA com data, categoria e valor (sempre positivo). O tipo (Entrada/Saída) é identificado pela categoria.
B14: Passo 5 | C14: Aba Fluxo Realizado: é montada sozinha a partir dos lançamentos, com totais por categoria, saldo do mês e saldo acumulado.
B15: Passo 6 | C15: Abas Previsto x Realizado e Painel: compare o planejado com o realizado, veja o menor saldo do ano e os meses em que o caixa fica negativo.
B17: Dicas
B18: • | C18: A coluna 'Situação' dos lançamentos avisa quando falta data, categoria ou valor, ou quando a data está fora dos 12 meses do controle.
B19: • | C19: Para controlar um novo ano, salve uma cópia do arquivo, altere o mês inicial na Config e use o saldo final como novo saldo inicial.
B20: • | C20: Financiamentos: lance a liberação do crédito como entrada e cada parcela paga como saída.
B21: • | C21: Capacidade: 10 categorias de entrada, 20 de saída e 1.500 lançamentos.
B23: Proteção das planilhas
C24: As abas estão protegidas SEM SENHA apenas para evitar exclusão acidental de fórmulas. Para personalizar: Excel → guia Revisão → Desproteger Planilha (no LibreOffice: Ferramentas → Proteger planilha; no Google Planilhas a proteção não é importada). Lembre-se de proteger novamente depois.
C26: Compatível com Microsoft Excel 2010 ou superior, LibreOffice Calc e Google Planilhas. A aba 'Exemplo' contém apenas dados FICTÍCIOS para demonstração e pode ser excluída.

Sheet Painel
A1: Painel do Fluxo de Caixa
A2: Visão geral dos 12 meses: realizado e previsto
B4: ="Propriedade: "&IF(Config!B5="","(informe na aba Config)",Config!B5)&" • Período: "&CHOOSE(MONTH(Config!B6),"jan","fev","mar","abr","mai","jun","jul","ago","set","out","nov","dez")&"/"&RIGHT(YEAR(Config!B6),2)&" a "&CHOOSE(MONTH(EDATE(Config!B6,11)),"jan","fev","mar","abr","mai","jun","jul","ago","set","out","nov","dez")&"/"&RIGHT(YEAR(EDATE(Config!B6,11)),2)
B5: Indicadores | E5: Mês a mês
B6: Saldo inicial | C6: =Config!B7 | E6: Mês | F6: Entradas previstas | G6: Entradas realizadas | H6: Saídas previstas | I6: Saídas realizadas | J6: Saldo acum. previsto | K6: Saldo acum. realizado
B7: Total de entradas (realizado) | C7: ='Fluxo Realizado'!N18 | E7: =CHOOSE(MONTH('Fluxo Realizado'!B5),"jan","fev","mar","abr","mai","jun","jul","ago","set","out","nov","dez")&"/"&RIGHT(YEAR('Fluxo Realizado'!B5),2) | F7: ='Previsto'!B18 | G7: ='Fluxo Realizado'!B18 | H7: ='Previsto'!B41 | I7: ='Fluxo Realizado'!B41 | J7: ='Previsto'!B46 | K7: ='Fluxo Realizado'!B46
B8: Total de saídas (realizado) | C8: ='Fluxo Realizado'!N41 | E8: =CHOOSE(MONTH('Fluxo Realizado'!C5),"jan","fev","mar","abr","mai","jun","jul","ago","set","out","nov","dez")&"/"&RIGHT(YEAR('Fluxo Realizado'!C5),2) | F8: ='Previsto'!C18 | G8: ='Fluxo Realizado'!C18 | H8: ='Previsto'!C41 | I8: ='Fluxo Realizado'!C41 | J8: ='Previsto'!C46 | K8: ='Fluxo Realizado'!C46
B9: Resultado do período | C9: =C7-C8 | E9: =CHOOSE(MONTH('Fluxo Realizado'!D5),"jan","fev","mar","abr","mai","jun","jul","ago","set","out","nov","dez")&"/"&RIGHT(YEAR('Fluxo Realizado'!D5),2) | F9: ='Previsto'!D18 | G9: ='Fluxo Realizado'!D18 | H9: ='Previsto'!D41 | I9: ='Fluxo Realizado'!D41 | J9: ='Previsto'!D46 | K9: ='Fluxo Realizado'!D46
B10: Saldo final acumulado (realizado) | C10: ='Fluxo Realizado'!M46 | E10: =CHOOSE(MONTH('Fluxo Realizado'!E5),"jan","fev","mar","abr","mai","jun","jul","ago","set","out","nov","dez")&"/"&RIGHT(YEAR('Fluxo Realizado'!E5),2) | F10: ='Previsto'!E18 | G10: ='Fluxo Realizado'!E18 | H10: ='Previsto'!E41 | I10: ='Fluxo Realizado'!E41 | J10: ='Previsto'!E46 | K10: ='Fluxo Realizado'!E46
B11: Menor saldo acumulado no período | C11: =MIN('Fluxo Realizado'!B46:M46) | E11: =CHOOSE(MONTH('Fluxo Realizado'!F5),"jan","fev","mar","abr","mai","jun","jul","ago","set","out","nov","dez")&"/"&RIGHT(YEAR('Fluxo Realizado'!F5),2) | F11: ='Previsto'!F18 | G11: ='Fluxo Realizado'!F18 | H11: ='Previsto'!F41 | I11: ='Fluxo Realizado'!F41 | J11: ='Previsto'!F46 | K11: ='Fluxo Realizado'!F46
B12: Mês do menor saldo | C12: =IFERROR(CHOOSE(MONTH(INDEX('Fluxo Realizado'!B5:M5,MATCH(C11,'Fluxo Realizado'!B46:M46,0))),"jan","fev","mar","abr","mai","jun","jul","ago","set","out","nov","dez")&"/"&RIGHT(YEAR(INDEX('Fluxo Realizado'!B5:M5,MATCH(C11,'Fluxo Realizado'!B46:M46,0))),2),"-") | E12: =CHOOSE(MONTH('Fluxo Realizado'!G5),"jan","fev","mar","abr","mai","jun","jul","ago","set","out","nov","dez")&"/"&RIGHT(YEAR('Fluxo Realizado'!G5),2) | F12: ='Previsto'!G18 | G12: ='Fluxo Realizado'!G18 | H12: ='Previsto'!G41 | I12: ='Fluxo Realizado'!G41 | J12: ='Previsto'!G46 | K12: ='Fluxo Realizado'!G46
B13: Meses com saldo negativo | C13: =COUNTIF('Fluxo Realizado'!B46:M46,"<0") | E13: =CHOOSE(MONTH('Fluxo Realizado'!H5),"jan","fev","mar","abr","mai","jun","jul","ago","set","out","nov","dez")&"/"&RIGHT(YEAR('Fluxo Realizado'!H5),2) | F13: ='Previsto'!H18 | G13: ='Fluxo Realizado'!H18 | H13: ='Previsto'!H41 | I13: ='Fluxo Realizado'!H41 | J13: ='Previsto'!H46 | K13: ='Fluxo Realizado'!H46
B14: Entradas previstas | C14: ='Previsto'!N18 | E14: =CHOOSE(MONTH('Fluxo Realizado'!I5),"jan","fev","mar","abr","mai","jun","jul","ago","set","out","nov","dez")&"/"&RIGHT(YEAR('Fluxo Realizado'!I5),2) | F14: ='Previsto'!I18 | G14: ='Fluxo Realizado'!I18 | H14: ='Previsto'!I41 | I14: ='Fluxo Realizado'!I41 | J14: ='Previsto'!I46 | K14: ='Fluxo Realizado'!I46
B15: Saídas previstas | C15: ='Previsto'!N41 | E15: =CHOOSE(MONTH('Fluxo Realizado'!J5),"jan","fev","mar","abr","mai","jun","jul","ago","set","out","nov","dez")&"/"&RIGHT(YEAR('Fluxo Realizado'!J5),2) | F15: ='Previsto'!J18 | G15: ='Fluxo Realizado'!J18 | H15: ='Previsto'!J41 | I15: ='Fluxo Realizado'!J41 | J15: ='Previsto'!J46 | K15: ='Fluxo Realizado'!J46
B16: Saldo final previsto | C16: ='Previsto'!M46 | E16: =CHOOSE(MONTH('Fluxo Realizado'!K5),"jan","fev","mar","abr","mai","jun","jul","ago","set","out","nov","dez")&"/"&RIGHT(YEAR('Fluxo Realizado'!K5),2) | F16: ='Previsto'!K18 | G16: ='Fluxo Realizado'!K18 | H16: ='Previsto'!K41 | I16: ='Fluxo Realizado'!K41 | J16: ='Previsto'!K46 | K16: ='Fluxo Realizado'!K46
B17: Diferença saldo final (realizado − previsto) | C17: =C10-C16 | E17: =CHOOSE(MONTH('Fluxo Realizado'!L5),"jan","fev","mar","abr","mai","jun","jul","ago","set","out","nov","dez")&"/"&RIGHT(YEAR('Fluxo Realizado'!L5),2) | F17: ='Previsto'!L18 | G17: ='Fluxo Realizado'!L18 | H17: ='Previsto'!L41 | I17: ='Fluxo Realizado'!L41 | J17: ='Previsto'!L46 | K17: ='Fluxo Realizado'!L46
B18: Lançamentos com pendência | C18: =SUMPRODUCT(('Lançamentos'!$I$6:$I$1505<>"")*('Lançamentos'!$I$6:$I$1505<>"OK")) | E18: =CHOOSE(MONTH('Fluxo Realizado'!M5),"jan","fev","mar","abr","mai","jun","jul","ago","set","out","nov","dez")&"/"&RIGHT(YEAR('Fluxo Realizado'!M5),2) | F18: ='Previsto'!M18 | G18: ='Fluxo Realizado'!M18 | H18: ='Previsto'!M41 | I18: ='Fluxo Realizado'!M41 | J18: ='Previsto'!M46 | K18: ='Fluxo Realizado'!M46
E19: TOTAL | F19: =SUM(F7:F18) | G19: =SUM(G7:G18) | H19: =SUM(H7:H18) | I19: =SUM(I7:I18) | J19: =J18 | K19: =K18

Sheet Config
A1: Configurações
A2: Período, saldo inicial e categorias
A3: Legenda: | B3: Preencher | C3: Cálculo automático (protegido)
A4: Dados gerais | D4: Categorias de ENTRADA | F4: Categorias de SAÍDA
A5: Nome da propriedade | D5: Entradas | F5: Saídas
A6: Mês inicial do controle | B6: =DATE(YEAR(TODAY()),1,1) | D6: Venda de grãos | F6: Sementes e mudas
A7: Saldo inicial em caixa (R$) | B7: 0 | D7: Venda de animais | F7: Fertilizantes e corretivos
D8: Venda de leite | F8: Defensivos
A9: O controle cobre 12 meses a partir do mês inicial. | D9: Venda de hortifrúti | F9: Ração e sal mineral
D10: Prestação de serviços | F10: Medicamentos veterinários
D11: Crédito rural / financiamento | F11: Combustível
D12: Outras receitas | F12: Manutenção de máquinas e benfeitorias
F13: Mão de obra e encargos
F14: Arrendamento
F15: Energia elétrica e água
F16: Parcelas de financiamento
F17: Impostos e taxas (ITR, Funrural etc.)
F18: Fretes
F19: Retiradas pessoais (pró-labore)
F20: Investimentos (máquinas, benfeitorias)
F21: Outras despesas

Sheet Lançamentos
A1: Lançamentos Realizados
A2: Registre aqui cada entrada e saída de dinheiro
A3: Legenda: | B3: Preencher | C3: Cálculo automático (protegido)
A5: Data | B5: Categoria | C5: Tipo | D5: Descrição | E5: Valor (R$) | F5: Forma de pagamento | G5: Conta / observação | H5: Mês nº | I5: Situação
C6: =IF(B6="","",IF(COUNTIF(Config!$D$6:$D$15,B6)>0,"Entrada",IF(COUNTIF(Config!$F$6:$F$25,B6)>0,"Saída","Categoria inválida"))) | H6: =IF(A6="","",(YEAR(A6)-YEAR(Config!$B$6))*12+MONTH(A6)-MONTH(Config!$B$6)+1) | I6: =IF(AND(A6="",B6="",E6=""),"",IF(A6="","Falta data",IF(B6="","Falta categoria",IF(E6="","Falta valor",IF(C6="Categoria inválida","Categoria inválida",IF(OR(H6<1,H6>12),"Fora dos 12 meses","OK"))))))
C7: =IF(B7="","",IF(COUNTIF(Config!$D$6:$D$15,B7)>0,"Entrada",IF(COUNTIF(Config!$F$6:$F$25,B7)>0,"Saída","Categoria inválida"))) | H7: =IF(A7="","",(YEAR(A7)-YEAR(Config!$B$6))*12+MONTH(A7)-MONTH(Config!$B$6)+1) | I7: =IF(AND(A7="",B7="",E7=""),"",IF(A7="","Falta data",IF(B7="","Falta categoria",IF(E7="","Falta valor",IF(C7="Categoria inválida","Categoria inválida",IF(OR(H7<1,H7>12),"Fora dos 12 meses","OK"))))))
C8: =IF(B8="","",IF(COUNTIF(Config!$D$6:$D$15,B8)>0,"Entrada",IF(COUNTIF(Config!$F$6:$F$25,B8)>0,"Saída","Categoria inválida"))) | H8: =IF(A8="","",(YEAR(A8)-YEAR(Config!$B$6))*12+MONTH(A8)-MONTH(Config!$B$6)+1) | I8: =IF(AND(A8="",B8="",E8=""),"",IF(A8="","Falta data",IF(B8="","Falta categoria",IF(E8="","Falta valor",IF(C8="Categoria inválida","Categoria inválida",IF(OR(H8<1,H8>12),"Fora dos 12 meses","OK"))))))
C9: =IF(B9="","",IF(COUNTIF(Config!$D$6:$D$15,B9)>0,"Entrada",IF(COUNTIF(Config!$F$6:$F$25,B9)>0,"Saída","Categoria inválida"))) | H9: =IF(A9="","",(YEAR(A9)-YEAR(Config!$B$6))*12+MONTH(A9)-MONTH(Config!$B$6)+1) | I9: =IF(AND(A9="",B9="",E9=""),"",IF(A9="","Falta data",IF(B9="","Falta categoria",IF(E9="","Falta valor",IF(C9="Categoria inválida","Categoria inválida",IF(OR(H9<1,H9>12),"Fora dos 12 meses","OK"))))))
C10: =IF(B10="","",IF(COUNTIF(Config!$D$6:$D$15,B10)>0,"Entrada",IF(COUNTIF(Config!$F$6:$F$25,B10)>0,"Saída","Categoria inválida"))) | H10: =IF(A10="","",(YEAR(A10)-YEAR(Config!$B$6))*12+MONTH(A10)-MONTH(Config!$B$6)+1) | I10: =IF(AND(A10="",B10="",E10=""),"",IF(A10="","Falta data",IF(B10="","Falta categoria",IF(E10="","Falta valor",IF(C10="Categoria inválida","Categoria inválida",IF(OR(H10<1,H10>12),"Fora dos 12 meses","OK"))))))
C11: =IF(B11="","",IF(COUNTIF(Config!$D$6:$D$15,B11)>0,"Entrada",IF(COUNTIF(Config!$F$6:$F$25,B11)>0,"Saída","Categoria inválida"))) | H11: =IF(A11="","",(YEAR(A11)-YEAR(Config!$B$6))*12+MONTH(A11)-MONTH(Config!$B$6)+1) | I11: =IF(AND(A11="",B11="",E11=""),"",IF(A11="","Falta data",IF(B11="","Falta categoria",IF(E11="","Falta valor",IF(C11="Categoria inválida","Categoria inválida",IF(OR(H11<1,H11>12),"Fora dos 12 meses","OK"))))))
C12: =IF(B12="","",IF(COUNTIF(Config!$D$6:$D$15,B12)>0,"Entrada",IF(COUNTIF(Config!$F$6:$F$25,B12)>0,"Saída","Categoria inválida"))) | H12: =IF(A12="","",(YEAR(A12)-YEAR(Config!$B$6))*12+MONTH(A12)-MONTH(Config!$B$6)+1) | I12: =IF(AND(A12="",B12="",E12=""),"",IF(A12="","Falta data",IF(B12="","Falta categoria",IF(E12="","Falta valor",IF(C12="Categoria inválida","Categoria inválida",IF(OR(H12<1,H12>12),"Fora dos 12 meses","OK"))))))
C13: =IF(B13="","",IF(COUNTIF(Config!$D$6:$D$15,B13)>0,"Entrada",IF(COUNTIF(Config!$F$6:$F$25,B13)>0,"Saída","Categoria inválida"))) | H13: =IF(A13="","",(YEAR(A13)-YEAR(Config!$B$6))*12+MONTH(A13)-MONTH(Config!$B$6)+1) | I13: =IF(AND(A13="",B13="",E13=""),"",IF(A13="","Falta data",IF(B13="","Falta categoria",IF(E13="","Falta valor",IF(C13="Categoria inválida","Categoria inválida",IF(OR(H13<1,H13>12),"Fora dos 12 meses","OK"))))))
C14: =IF(B14="","",IF(COUNTIF(Config!$D$6:$D$15,B14)>0,"Entrada",IF(COUNTIF(Config!$F$6:$F$25,B14)>0,"Saída","Categoria inválida"))) | H14: =IF(A14="","",(YEAR(A14)-YEAR(Config!$B$6))*12+MONTH(A14)-MONTH(Config!$B$6)+1) | I14: =IF(AND(A14="",B14="",E14=""),"",IF(A14="","Falta data",IF(B14="","Falta categoria",IF(E14="","Falta valor",IF(C14="Categoria inválida","Categoria inválida",IF(OR(H14<1,H14>12),"Fora dos 12 meses","OK"))))))
C15: =IF(B15="","",IF(COUNTIF(Config!$D$6:$D$15,B15)>0,"Entrada",IF(COUNTIF(Config!$F$6:$F$25,B15)>0,"Saída","Categoria inválida"))) | H15: =IF(A15="","",(YEAR(A15)-YEAR(Config!$B$6))*12+MONTH(A15)-MONTH(Config!$B$6)+1) | I15: =IF(AND(A15="",B15="",E15=""),"",IF(A15="","Falta data",IF(B15="","Falta categoria",IF(E15="","Falta valor",IF(C15="Categoria inválida","Categoria inválida",IF(OR(H15<1,H15>12),"Fora dos 12 meses","OK"))))))
C16: =IF(B16="","",IF(COUNTIF(Config!$D$6:$D$15,B16)>0,"Entrada",IF(COUNTIF(Config!$F$6:$F$25,B16)>0,"Saída","Categoria inválida"))) | H16: =IF(A16="","",(YEAR(A16)-YEAR(Config!$B$6))*12+MONTH(A16)-MONTH(Config!$B$6)+1) | I16: =IF(AND(A16="",B16="",E16=""),"",IF(A16="","Falta data",IF(B16="","Falta categoria",IF(E16="","Falta valor",IF(C16="Categoria inválida","Categoria inválida",IF(OR(H16<1,H16>12),"Fora dos 12 meses","OK"))))))
C17: =IF(B17="","",IF(COUNTIF(Config!$D$6:$D$15,B17)>0,"Entrada",IF(COUNTIF(Config!$F$6:$F$25,B17)>0,"Saída","Categoria inválida"))) | H17: =IF(A17="","",(YEAR(A17)-YEAR(Config!$B$6))*12+MONTH(A17)-MONTH(Config!$B$6)+1) | I17: =IF(AND(A17="",B17="",E17=""),"",IF(A17="","Falta data",IF(B17="","Falta categoria",IF(E17="","Falta valor",IF(C17="Categoria inválida","Categoria inválida",IF(OR(H17<1,H17>12),"Fora dos 12 meses","OK"))))))
... C1505: =IF(B1505="","",IF(COUNTIF(Config!$D$6:$D$15,B1505)>0,"Entrada",IF(COUNTIF(Config!$F$6:$F$25,B1505)>0,"Saída","Categoria inválida"))) | H1505: =IF(A1505="","",(YEAR(A1505)-YEAR(Config!$B$6))*12+MONTH(A1505)-MONTH(Config!$B$6)+1) | I1505: =IF(AND(A1505="",B1505="",E1505=""),"",IF(A1505="","Falta data",IF(B1505="","Falta categoria",IF(E1505="","Falta valor",IF(C1505="Categoria inválida","Categoria inválida",IF(OR(H1505<1,H1505>12),"Fora dos 12 meses","OK"))))))

Sheet Previsto
A1: Fluxo Previsto (Orçamento)
A2: Digite os valores que você espera receber e pagar em cada mês
A3: Legenda: | B3: Preencher | C3: Cálculo automático (protegido)
A5: Categoria | B5: =EDATE(Config!$B$6,0) | C5: =EDATE(Config!$B$6,1) | D5: =EDATE(Config!$B$6,2) | E5: =EDATE(Config!$B$6,3) | F5: =EDATE(Config!$B$6,4) | G5: =EDATE(Config!$B$6,5) | H5: =EDATE(Config!$B$6,6) | I5: =EDATE(Config!$B$6,7) | J5: =EDATE(Config!$B$6,8) | K5: =EDATE(Config!$B$6,9) | L5: =EDATE(Config!$B$6,10) | M5: =EDATE(Config!$B$6,11) | N5: Total 12 meses
A7: ENTRADAS
A8: =IF(Config!$D6="","",Config!$D6) | N8: =IF($A8="","",SUM(B8:M8))
A9: =IF(Config!$D7="","",Config!$D7) | N9: =IF($A9="","",SUM(B9:M9))
A10: =IF(Config!$D8="","",Config!$D8) | N10: =IF($A10="","",SUM(B10:M10))
A11: =IF(Config!$D9="","",Config!$D9) | N11: =IF($A11="","",SUM(B11:M11))
A12: =IF(Config!$D10="","",Config!$D10) | N12: =IF($A12="","",SUM(B12:M12))
A13: =IF(Config!$D11="","",Config!$D11) | N13: =IF($A13="","",SUM(B13:M13))
A14: =IF(Config!$D12="","",Config!$D12) | N14: =IF($A14="","",SUM(B14:M14))
A15: =IF(Config!$D13="","",Config!$D13) | N15: =IF($A15="","",SUM(B15:M15))
A16: =IF(Config!$D14="","",Config!$D14) | N16: =IF($A16="","",SUM(B16:M16))
A17: =IF(Config!$D15="","",Config!$D15) | N17: =IF($A17="","",SUM(B17:M17))
A18: TOTAL ENTRADAS | B18: =SUM(B8:B17) | C18: =SUM(C8:C17) | D18: =SUM(D8:D17) | E18: =SUM(E8:E17) | F18: =SUM(F8:F17) | G18: =SUM(G8:G17) | H18: =SUM(H8:H17) | I18: =SUM(I8:I17) | ... N18: =SUM(N8:N17)
A20: SAÍDAS
A21: =IF(Config!$F6="","",Config!$F6) | N21: =IF($A21="","",SUM(B21:M21))
A22: =IF(Config!$F7="","",Config!$F7) | N22: =IF($A22="","",SUM(B22:M22))
A23: =IF(Config!$F8="","",Config!$F8) | N23: =IF($A23="","",SUM(B23:M23))
A24: =IF(Config!$F9="","",Config!$F9) | N24: =IF($A24="","",SUM(B24:M24))
A25: =IF(Config!$F10="","",Config!$F10) | N25: =IF($A25="","",SUM(B25:M25))
A26: =IF(Config!$F11="","",Config!$F11) | N26: =IF($A26="","",SUM(B26:M26))
A27: =IF(Config!$F12="","",Config!$F12) | N27: =IF($A27="","",SUM(B27:M27))
A28: =IF(Config!$F13="","",Config!$F13) | N28: =IF($A28="","",SUM(B28:M28))
A29: =IF(Config!$F14="","",Config!$F14) | N29: =IF($A29="","",SUM(B29:M29))
A30: =IF(Config!$F15="","",Config!$F15) | N30: =IF($A30="","",SUM(B30:M30))
A31: =IF(Config!$F16="","",Config!$F16) | N31: =IF($A31="","",SUM(B31:M31))
A32: =IF(Config!$F17="","",Config!$F17) | N32: =IF($A32="","",SUM(B32:M32))
... A40: =IF(Config!$F25="","",Config!$F25) | N40: =IF($A40="","",SUM(B40:M40))
A41: TOTAL SAÍDAS | B41: =SUM(B21:B40) | C41: =SUM(C21:C40) | D41: =SUM(D21:D40) | E41: =SUM(E21:E40) | F41: =SUM(F21:F40) | G41: =SUM(G21:G40) | H41: =SUM(H21:H40) | I41: =SUM(I21:I40) | ... N41: =SUM(N21:N40)
A43: RESULTADO
A44: Saldo do mês (entradas − saídas) | B44: =B18-B41 | C44: =C18-C41 | D44: =D18-D41 | E44: =E18-E41 | F44: =F18-F41 | G44: =G18-G41 | H44: =H18-H41 | I44: =I18-I41 | ... N44: =N18-N41
A45: Saldo inicial do mês | B45: =Config!$B$7 | C45: =B46 | D45: =C46 | E45: =D46 | F45: =E46 | G45: =F46 | H45: =G46 | I45: =H46 | J45: =I46 | ... M45: =L46 | N45: =B45
A46: Saldo acumulado (final do mês) | B46: =B45+B44 | C46: =C45+C44 | D46: =D45+D44 | E46: =E45+E44 | F46: =F45+F44 | G46: =G45+G44 | H46: =H45+H44 | I46: =I45+I44 | ... M46: =M45+M44 | N46: =M46

Sheet Fluxo Realizado
A1: Fluxo de Caixa Realizado
A2: Calculado automaticamente a partir da aba Lançamentos
A3: Legenda: | B3: Preencher | C3: Cálculo automático (protegido)
A5: Categoria | B5: =EDATE(Config!$B$6,0) | C5: =EDATE(Config!$B$6,1) | D5: =EDATE(Config!$B$6,2) | E5: =EDATE(Config!$B$6,3) | F5: =EDATE(Config!$B$6,4) | G5: =EDATE(Config!$B$6,5) | H5: =EDATE(Config!$B$6,6) | I5: =EDATE(Config!$B$6,7) | J5: =EDATE(Config!$B$6,8) | K5: =EDATE(Config!$B$6,9) | L5: =EDATE(Config!$B$6,10) | M5: =EDATE(Config!$B$6,11) | N5: Total 12 meses
A7: ENTRADAS
A8: =IF(Config!$D6="","",Config!$D6) | B8: =IF($A8="","",SUMIFS('Lançamentos'!$E$6:$E$1505,'Lançamentos'!$B$6:$B$1505,$A8,'Lançamentos'!$H$6:$H$1505,1)) | C8: =IF($A8="","",SUMIFS('Lançamentos'!$E$6:$E$1505,'Lançamentos'!$B$6:$B$1505,$A8,'Lançamentos'!$H$6:$H$1505,2)) | D8: =IF($A8="","",SUMIFS('Lançamentos'!$E$6:$E$1505,'Lançamentos'!$B$6:$B$1505,$A8,'Lançamentos'!$H$6:$H$1505,3)) | E8: =IF($A8="","",SUMIFS('Lançamentos'!$E$6:$E$1505,'Lançamentos'!$B$6:$B$1505,$A8,'Lançamentos'!$H$6:$H$1505,4)) | F8: =IF($A8="","",SUMIFS('Lançamentos'!$E$6:$E$1505,'Lançamentos'!$B$6:$B$1505,$A8,'Lançamentos'!$H$6:$H$1505,5)) | G8: =IF($A8="","",SUMIFS('Lançamentos'!$E$6:$E$1505,'Lançamentos'!$B$6:$B$1505,$A8,'Lançamentos'!$H$6:$H$1505,6)) | H8: =IF($A8="","",SUMIFS('Lançamentos'!$E$6:$E$1505,'Lançamentos'!$B$6:$B$1505,$A8,'Lançamentos'!$H$6:$H$1505,7)) | I8: =IF($A8="","",SUMIFS('Lançamentos'!$E$6:$E$1505,'Lançamentos'!$B$6:$B$1505,$A8,'Lançamentos'!$H$6:$H$1505,8)) | J8: =IF($A8="","",SUMIFS('Lançamentos'!$E$6:$E$1505,'Lançamentos'!$B$6:$B$1505,$A8,'Lançamentos'!$H$6:$H$1505,9)) | K8: =IF($A8="","",SUMIFS('Lançamentos'!$E$6:$E$1505,'Lançamentos'!$B$6:$B$1505,$A8,'Lançamentos'!$H$6:$H$1505,10)) | L8: =IF($A8="","",SUMIFS('Lançamentos'!$E$6:$E$1505,'Lançamentos'!$B$6:$B$1505,$A8,'Lançamentos'!$H$6:$H$1505,11)) | M8: =IF($A8="","",SUMIFS('Lançamentos'!$E$6:$E$1505,'Lançamentos'!$B$6:$B$1505,$A8,'Lançamentos'!$H$6:$H$1505,12)) | N8: =IF($A8="","",SUM(B8:M8))
A9: =IF(Config!$D7="","",Config!$D7) | B9: =IF($A9="","",SUMIFS('Lançamentos'!$E$6:$E$1505,'Lançamentos'!$B$6:$B$1505,$A9,'Lançamentos'!$H$6:$H$1505,1)) | C9: =IF($A9="","",SUMIFS('Lançamentos'!$E$6:$E$1505,'Lançamentos'!$B$6:$B$1505,$A9,'Lançamentos'!$H$6:$H$1505,2)) | D9: =IF($A9="","",SUMIFS('Lançamentos'!$E$6:$E$1505,'Lançamentos'!$B$6:$B$1505,$A9,'Lançamentos'!$H$6:$H$1505,3)) | E9: =IF($A9="","",SUMIFS('Lançamentos'!$E$6:$E$1505,'Lançamentos'!$B$6:$B$1505,$A9,'Lançamentos'!$H$6:$H$1505,4)) | F9: =IF($A9="","",SUMIFS('Lançamentos'!$E$6:$E$1505,'Lançamentos'!$B$6:$B$1505,$A9,'Lançamentos'!$H$6:$H$1505,5)) | G9: =IF($A9="","",SUMIFS('Lançamentos'!$E$6:$E$1505,'Lançamentos'!$B$6:$B$1505,$A9,'Lançamentos'!$H$6:$H$1505,6)) | H9: =IF($A9="","",SUMIFS('Lançamentos'!$E$6:$E$1505,'Lançamentos'!$B$6:$B$1505,$A9,'Lançamentos'!$H$6:$H$1505,7)) | I9: =IF($A9="","",SUMIFS('Lançamentos'!$E$6:$E$1505,'Lançamentos'!$B$6:$B$1505,$A9,'Lançamentos'!$H$6:$H$1505,8)) | J9: =IF($A9="","",SUMIFS('Lançamentos'!$E$6:$E$1505,'Lançamentos'!$B$6:$B$1505,$A9,'Lançamentos'!$H$6:$H$1505,9)) | K9: =IF($A9="","",SUMIFS('Lançamentos'!$E$6:$E$1505,'Lançamentos'!$B$6:$B$1505,$A9,'Lançamentos'!$H$6:$H$1505,10)) | L9: =IF($A9="","",SUMIFS('Lançamentos'!$E$6:$E$1505,'Lançamentos'!$B$6:$B$1505,$A9,'Lançamentos'!$H$6:$H$1505,11)) | M9: =IF($A9="","",SUMIFS('Lançamentos'!$E$6:$E$1505,'Lançamentos'!$B$6:$B$1505,$A9,'Lançamentos'!$H$6:$H$1505,12)) | N9: =IF($A9="","",SUM(B9:M9))
A10: =IF(Config!$D8="","",Config!$D8) | B10: =IF($A10="","",SUMIFS('Lançamentos'!$E$6:$E$1505,'Lançamentos'!$B$6:$B$1505,$A10,'Lançamentos'!$H$6:$H$1505,1)) | C10: =IF($A10="","",SUMIFS('Lançamentos'!$E$6:$E$1505,'Lançamentos'!$B$6:$B$1505,$A10,'Lançamentos'!$H$6:$H$1505,2)) | D10: =IF($A10="","",SUMIFS('Lançamentos'!$E$6:$E$1505,'Lançamentos'!$B$6:$B$1505,$A10,'Lançamentos'!$H$6:$H$1505,3)) | E10: =IF($A10="","",SUMIFS('Lançamentos'!$E$6:$E$1505,'Lançamentos'!$B$6:$B$1505,$A10,'Lançamentos'!$H$6:$H$1505,4)) | F10: =IF($A10="","",SUMIFS('Lançamentos'!$E$6:$E$1505,'Lançamentos'!$B$6:$B$1505,$A10,'Lançamentos'!$H$6:$H$1505,5)) | G10: =IF($A10="","",SUMIFS('Lançamentos'!$E$6:$E$1505,'Lançamentos'!$B$6:$B$1505,$A10,'Lançamentos'!$H$6:$H$1505,6)) | H10: =IF($A10="","",SUMIFS('Lançamentos'!$E$6:$E$1505,'Lançamentos'!$B$6:$B$1505,$A10,'Lançamentos'!$H$6:$H$1505,7)) | I10: =IF($A10="","",SUMIFS('Lançamentos'!$E$6:$E$1505,'Lançamentos'!$B$6:$B$1505,$A10,'Lançamentos'!$H$6:$H$1505,8)) | J10: =IF($A10="","",SUMIFS('Lançamentos'!$E$6:$E$1505,'Lançamentos'!$B$6:$B$1505,$A10,'Lançamentos'!$H$6:$H$1505,9)) | K10: =IF($A10="","",SUMIFS('Lançamentos'!$E$6:$E$1505,'Lançamentos'!$B$6:$B$1505,$A10,'Lançamentos'!$H$6:$H$1505,10)) | L10: =IF($A10="","",SUMIFS('Lançamentos'!$E$6:$E$1505,'Lançamentos'!$B$6:$B$1505,$A10,'Lançamentos'!$H$6:$H$1505,11)) | M10: =IF($A10="","",SUMIFS('Lançamentos'!$E$6:$E$1505,'Lançamentos'!$B$6:$B$1505,$A10,'Lançamentos'!$H$6:$H$1505,12)) | N10: =IF($A10="","",SUM(B10:M10))
A11: =IF(Config!$D9="","",Config!$D9) | B11: =IF($A11="","",SUMIFS('Lançamentos'!$E$6:$E$1505,'Lançamentos'!$B$6:$B$1505,$A11,'Lançamentos'!$H$6:$H$1505,1)) | C11: =IF($A11="","",SUMIFS('Lançamentos'!$E$6:$E$1505,'Lançamentos'!$B$6:$B$1505,$A11,'Lançamentos'!$H$6:$H$1505,2)) | D11: =IF($A11="","",SUMIFS('Lançamentos'!$E$6:$E$1505,'Lançamentos'!$B$6:$B$1505,$A11,'Lançamentos'!$H$6:$H$1505,3)) | E11: =IF($A11="","",SUMIFS('Lançamentos'!$E$6:$E$1505,'Lançamentos'!$B$6:$B$1505,$A11,'Lançamentos'!$H$6:$H$1505,4)) | F11: =IF($A11="","",SUMIFS('Lançamentos'!$E$6:$E$1505,'Lançamentos'!$B$6:$B$1505,$A11,'Lançamentos'!$H$6:$H$1505,5)) | G11: =IF($A11="","",SUMIFS('Lançamentos'!$E$6:$E$1505,'Lançamentos'!$B$6:$B$1505,$A11,'Lançamentos'!$H$6:$H$1505,6)) | H11: =IF($A11="","",SUMIFS('Lançamentos'!$E$6:$E$1505,'Lançamentos'!$B$6:$B$1505,$A11,'Lançamentos'!$H$6:$H$1505,7)) | I11: =IF($A11="","",SUMIFS('Lançamentos'!$E$6:$E$1505,'Lançamentos'!$B$6:$B$1505,$A11,'Lançamentos'!$H$6:$H$1505,8)) | J11: =IF($A11="","",SUMIFS('Lançamentos'!$E$6:$E$1505,'Lançamentos'!$B$6:$B$1505,$A11,'Lançamentos'!$H$6:$H$1505,9)) | K11: =IF($A11="","",SUMIFS('Lançamentos'!$E$6:$E$1505,'Lançamentos'!$B$6:$B$1505,$A11,'Lançamentos'!$H$6:$H$1505,10)) | L11: =IF($A11="","",SUMIFS('Lançamentos'!$E$6:$E$1505,'Lançamentos'!$B$6:$B$1505,$A11,'Lançamentos'!$H$6:$H$1505,11)) | M11: =IF($A11="","",SUMIFS('Lançamentos'!$E$6:$E$1505,'Lançamentos'!$B$6:$B$1505,$A11,'Lançamentos'!$H$6:$H$1505,12)) | N11: =IF($A11="","",SUM(B11:M11))
A12: =IF(Config!$D10="","",Config!$D10) | B12: =IF($A12="","",SUMIFS('Lançamentos'!$E$6:$E$1505,'Lançamentos'!$B$6:$B$1505,$A12,'Lançamentos'!$H$6:$H$1505,1)) | C12: =IF($A12="","",SUMIFS('Lançamentos'!$E$6:$E$1505,'Lançamentos'!$B$6:$B$1505,$A12,'Lançamentos'!$H$6:$H$1505,2)) | D12: =IF($A12="","",SUMIFS('Lançamentos'!$E$6:$E$1505,'Lançamentos'!$B$6:$B$1505,$A12,'Lançamentos'!$H$6:$H$1505,3)) | E12: =IF($A12="","",SUMIFS('Lançamentos'!$E$6:$E$1505,'Lançamentos'!$B$6:$B$1505,$A12,'Lançamentos'!$H$6:$H$1505,4)) | F12: =IF($A12="","",SUMIFS('Lançamentos'!$E$6:$E$1505,'Lançamentos'!$B$6:$B$1505,$A12,'Lançamentos'!$H$6:$H$1505,5)) | G12: =IF($A12="","",SUMIFS('Lançamentos'!$E$6:$E$1505,'Lançamentos'!$B$6:$B$1505,$A12,'Lançamentos'!$H$6:$H$1505,6)) | H12: =IF($A12="","",SUMIFS('Lançamentos'!$E$6:$E$1505,'Lançamentos'!$B$6:$B$1505,$A12,'Lançamentos'!$H$6:$H$1505,7)) | I12: =IF($A12="","",SUMIFS('Lançamentos'!$E$6:$E$1505,'Lançamentos'!$B$6:$B$1505,$A12,'Lançamentos'!$H$6:$H$1505,8)) | J12: =IF($A12="","",SUMIFS('Lançamentos'!$E$6:$E$1505,'Lançamentos'!$B$6:$B$1505,$A12,'Lançamentos'!$H$6:$H$1505,9)) | K12: =IF($A12="","",SUMIFS('Lançamentos'!$E$6:$E$1505,'Lançamentos'!$B$6:$B$1505,$A12,'Lançamentos'!$H$6:$H$1505,10)) | L12: =IF($A12="","",SUMIFS('Lançamentos'!$E$6:$E$1505,'Lançamentos'!$B$6:$B$1505,$A12,'Lançamentos'!$H$6:$H$1505,11)) | M12: =IF($A12="","",SUMIFS('Lançamentos'!$E$6:$E$1505,'Lançamentos'!$B$6:$B$1505,$A12,'Lançamentos'!$H$6:$H$1505,12)) | N12: =IF($A12="","",SUM(B12:M12))
A13: =IF(Config!$D11="","",Config!$D11) | B13: =IF($A13="","",SUMIFS('Lançamentos'!$E$6:$E$1505,'Lançamentos'!$B$6:$B$1505,$A13,'Lançamentos'!$H$6:$H$1505,1)) | C13: =IF($A13="","",SUMIFS('Lançamentos'!$E$6:$E$1505,'Lançamentos'!$B$6:$B$1505,$A13,'Lançamentos'!$H$6:$H$1505,2)) | D13: =IF($A13="","",SUMIFS('Lançamentos'!$E$6:$E$1505,'Lançamentos'!$B$6:$B$1505,$A13,'Lançamentos'!$H$6:$H$1505,3)) | E13: =IF($A13="","",SUMIFS('Lançamentos'!$E$6:$E$1505,'Lançamentos'!$B$6:$B$1505,$A13,'Lançamentos'!$H$6:$H$1505,4)) | F13: =IF($A13="","",SUMIFS('Lançamentos'!$E$6:$E$1505,'Lançamentos'!$B$6:$B$1505,$A13,'Lançamentos'!$H$6:$H$1505,5)) | G13: =IF($A13="","",SUMIFS('Lançamentos'!$E$6:$E$1505,'Lançamentos'!$B$6:$B$1505,$A13,'Lançamentos'!$H$6:$H$1505,6)) | H13: =IF($A13="","",SUMIFS('Lançamentos'!$E$6:$E$1505,'Lançamentos'!$B$6:$B$1505,$A13,'Lançamentos'!$H$6:$H$1505,7)) | I13: =IF($A13="","",SUMIFS('Lançamentos'!$E$6:$E$1505,'Lançamentos'!$B$6:$B$1505,$A13,'Lançamentos'!$H$6:$H$1505,8)) | J13: =IF($A13="","",SUMIFS('Lançamentos'!$E$6:$E$1505,'Lançamentos'!$B$6:$B$1505,$A13,'Lançamentos'!$H$6:$H$1505,9)) | K13: =IF($A13="","",SUMIFS('Lançamentos'!$E$6:$E$1505,'Lançamentos'!$B$6:$B$1505,$A13,'Lançamentos'!$H$6:$H$1505,10)) | L13: =IF($A13="","",SUMIFS('Lançamentos'!$E$6:$E$1505,'Lançamentos'!$B$6:$B$1505,$A13,'Lançamentos'!$H$6:$H$1505,11)) | M13: =IF($A13="","",SUMIFS('Lançamentos'!$E$6:$E$1505,'Lançamentos'!$B$6:$B$1505,$A13,'Lançamentos'!$H$6:$H$1505,12)) | N13: =IF($A13="","",SUM(B13:M13))
A14: =IF(Config!$D12="","",Config!$D12) | B14: =IF($A14="","",SUMIFS('Lançamentos'!$E$6:$E$1505,'Lançamentos'!$B$6:$B$1505,$A14,'Lançamentos'!$H$6:$H$1505,1)) | C14: =IF($A14="","",SUMIFS('Lançamentos'!$E$6:$E$1505,'Lançamentos'!$B$6:$B$1505,$A14,'Lançamentos'!$H$6:$H$1505,2)) | D14: =IF($A14="","",SUMIFS('Lançamentos'!$E$6:$E$1505,'Lançamentos'!$B$6:$B$1505,$A14,'Lançamentos'!$H$6:$H$1505,3)) | E14: =IF($A14="","",SUMIFS('Lançamentos'!$E$6:$E$1505,'Lançamentos'!$B$6:$B$1505,$A14,'Lançamentos'!$H$6:$H$1505,4)) | F14: =IF($A14="","",SUMIFS('Lançamentos'!$E$6:$E$1505,'Lançamentos'!$B$6:$B$1505,$A14,'Lançamentos'!$H$6:$H$1505,5)) | G14: =IF($A14="","",SUMIFS('Lançamentos'!$E$6:$E$1505,'Lançamentos'!$B$6:$B$1505,$A14,'Lançamentos'!$H$6:$H$1505,6)) | H14: =IF($A14="","",SUMIFS('Lançamentos'!$E$6:$E$1505,'Lançamentos'!$B$6:$B$1505,$A14,'Lançamentos'!$H$6:$H$1505,7)) | I14: =IF($A14="","",SUMIFS('Lançamentos'!$E$6:$E$1505,'Lançamentos'!$B$6:$B$1505,$A14,'Lançamentos'!$H$6:$H$1505,8)) | J14: =IF($A14="","",SUMIFS('Lançamentos'!$E$6:$E$1505,'Lançamentos'!$B$6:$B$1505,$A14,'Lançamentos'!$H$6:$H$1505,9)) | K14: =IF($A14="","",SUMIFS('Lançamentos'!$E$6:$E$1505,'Lançamentos'!$B$6:$B$1505,$A14,'Lançamentos'!$H$6:$H$1505,10)) | L14: =IF($A14="","",SUMIFS('Lançamentos'!$E$6:$E$1505,'Lançamentos'!$B$6:$B$1505,$A14,'Lançamentos'!$H$6:$H$1505,11)) | M14: =IF($A14="","",SUMIFS('Lançamentos'!$E$6:$E$1505,'Lançamentos'!$B$6:$B$1505,$A14,'Lançamentos'!$H$6:$H$1505,12)) | N14: =IF($A14="","",SUM(B14:M14))
A15: =IF(Config!$D13="","",Config!$D13) | B15: =IF($A15="","",SUMIFS('Lançamentos'!$E$6:$E$1505,'Lançamentos'!$B$6:$B$1505,$A15,'Lançamentos'!$H$6:$H$1505,1)) | C15: =IF($A15="","",SUMIFS('Lançamentos'!$E$6:$E$1505,'Lançamentos'!$B$6:$B$1505,$A15,'Lançamentos'!$H$6:$H$1505,2)) | D15: =IF($A15="","",SUMIFS('Lançamentos'!$E$6:$E$1505,'Lançamentos'!$B$6:$B$1505,$A15,'Lançamentos'!$H$6:$H$1505,3)) | E15: =IF($A15="","",SUMIFS('Lançamentos'!$E$6:$E$1505,'Lançamentos'!$B$6:$B$1505,$A15,'Lançamentos'!$H$6:$H$1505,4)) | F15: =IF($A15="","",SUMIFS('Lançamentos'!$E$6:$E$1505,'Lançamentos'!$B$6:$B$1505,$A15,'Lançamentos'!$H$6:$H$1505,5)) | G15: =IF($A15="","",SUMIFS('Lançamentos'!$E$6:$E$1505,'Lançamentos'!$B$6:$B$1505,$A15,'Lançamentos'!$H$6:$H$1505,6)) | H15: =IF($A15="","",SUMIFS('Lançamentos'!$E$6:$E$1505,'Lançamentos'!$B$6:$B$1505,$A15,'Lançamentos'!$H$6:$H$1505,7)) | I15: =IF($A15="","",SUMIFS('Lançamentos'!$E$6:$E$1505,'Lançamentos'!$B$6:$B$1505,$A15,'Lançamentos'!$H$6:$H$1505,8)) | J15: =IF($A15="","",SUMIFS('Lançamentos'!$E$6:$E$1505,'Lançamentos'!$B$6:$B$1505,$A15,'Lançamentos'!$H$6:$H$1505,9)) | K15: =IF($A15="","",SUMIFS('Lançamentos'!$E$6:$E$1505,'Lançamentos'!$B$6:$B$1505,$A15,'Lançamentos'!$H$6:$H$1505,10)) | L15: =IF($A15="","",SUMIFS('Lançamentos'!$E$6:$E$1505,'Lançamentos'!$B$6:$B$1505,$A15,'Lançamentos'!$H$6:$H$1505,11)) | M15: =IF($A15="","",SUMIFS('Lançamentos'!$E$6:$E$1505,'Lançamentos'!$B$6:$B$1505,$A15,'Lançamentos'!$H$6:$H$1505,12)) | N15: =IF($A15="","",SUM(B15:M15))
A16: =IF(Config!$D14="","",Config!$D14) | B16: =IF($A16="","",SUMIFS('Lançamentos'!$E$6:$E$1505,'Lançamentos'!$B$6:$B$1505,$A16,'Lançamentos'!$H$6:$H$1505,1)) | C16: =IF($A16="","",SUMIFS('Lançamentos'!$E$6:$E$1505,'Lançamentos'!$B$6:$B$1505,$A16,'Lançamentos'!$H$6:$H$1505,2)) | D16: =IF($A16="","",SUMIFS('Lançamentos'!$E$6:$E$1505,'Lançamentos'!$B$6:$B$1505,$A16,'Lançamentos'!$H$6:$H$1505,3)) | E16: =IF($A16="","",SUMIFS('Lançamentos'!$E$6:$E$1505,'Lançamentos'!$B$6:$B$1505,$A16,'Lançamentos'!$H$6:$H$1505,4)) | F16: =IF($A16="","",SUMIFS('Lançamentos'!$E$6:$E$1505,'Lançamentos'!$B$6:$B$1505,$A16,'Lançamentos'!$H$6:$H$1505,5)) | G16: =IF($A16="","",SUMIFS('Lançamentos'!$E$6:$E$1505,'Lançamentos'!$B$6:$B$1505,$A16,'Lançamentos'!$H$6:$H$1505,6)) | H16: =IF($A16="","",SUMIFS('Lançamentos'!$E$6:$E$1505,'Lançamentos'!$B$6:$B$1505,$A16,'Lançamentos'!$H$6:$H$1505,7)) | I16: =IF($A16="","",SUMIFS('Lançamentos'!$E$6:$E$1505,'Lançamentos'!$B$6:$B$1505,$A16,'Lançamentos'!$H$6:$H$1505,8)) | J16: =IF($A16="","",SUMIFS('Lançamentos'!$E$6:$E$1505,'Lançamentos'!$B$6:$B$1505,$A16,'Lançamentos'!$H$6:$H$1505,9)) | K16: =IF($A16="","",SUMIFS('Lançamentos'!$E$6:$E$1505,'Lançamentos'!$B$6:$B$1505,$A16,'Lançamentos'!$H$6:$H$1505,10)) | L16: =IF($A16="","",SUMIFS('Lançamentos'!$E$6:$E$1505,'Lançamentos'!$B$6:$B$1505,$A16,'Lançamentos'!$H$6:$H$1505,11)) | M16: =IF($A16="","",SUMIFS('Lançamentos'!$E$6:$E$1505,'Lançamentos'!$B$6:$B$1505,$A16,'Lançamentos'!$H$6:$H$1505,12)) | N16: =IF($A16="","",SUM(B16:M16))
A17: =IF(Config!$D15="","",Config!$D15) | B17: =IF($A17="","",SUMIFS('Lançamentos'!$E$6:$E$1505,'Lançamentos'!$B$6:$B$1505,$A17,'Lançamentos'!$H$6:$H$1505,1)) | C17: =IF($A17="","",SUMIFS('Lançamentos'!$E$6:$E$1505,'Lançamentos'!$B$6:$B$1505,$A17,'Lançamentos'!$H$6:$H$1505,2)) | D17: =IF($A17="","",SUMIFS('Lançamentos'!$E$6:$E$1505,'Lançamentos'!$B$6:$B$1505,$A17,'Lançamentos'!$H$6:$H$1505,3)) | E17: =IF($A17="","",SUMIFS('Lançamentos'!$E$6:$E$1505,'Lançamentos'!$B$6:$B$1505,$A17,'Lançamentos'!$H$6:$H$1505,4)) | F17: =IF($A17="","",SUMIFS('Lançamentos'!$E$6:$E$1505,'Lançamentos'!$B$6:$B$1505,$A17,'Lançamentos'!$H$6:$H$1505,5)) | G17: =IF($A17="","",SUMIFS('Lançamentos'!$E$6:$E$1505,'Lançamentos'!$B$6:$B$1505,$A17,'Lançamentos'!$H$6:$H$1505,6)) | H17: =IF($A17="","",SUMIFS('Lançamentos'!$E$6:$E$1505,'Lançamentos'!$B$6:$B$1505,$A17,'Lançamentos'!$H$6:$H$1505,7)) | I17: =IF($A17="","",SUMIFS('Lançamentos'!$E$6:$E$1505,'Lançamentos'!$B$6:$B$1505,$A17,'Lançamentos'!$H$6:$H$1505,8)) | J17: =IF($A17="","",SUMIFS('Lançamentos'!$E$6:$E$1505,'Lançamentos'!$B$6:$B$1505,$A17,'Lançamentos'!$H$6:$H$1505,9)) | K17: =IF($A17="","",SUMIFS('Lançamentos'!$E$6:$E$1505,'Lançamentos'!$B$6:$B$1505,$A17,'Lançamentos'!$H$6:$H$1505,10)) | L17: =IF($A17="","",SUMIFS('Lançamentos'!$E$6:$E$1505,'Lançamentos'!$B$6:$B$1505,$A17,'Lançamentos'!$H$6:$H$1505,11)) | M17: =IF($A17="","",SUMIFS('Lançamentos'!$E$6:$E$1505,'Lançamentos'!$B$6:$B$1505,$A17,'Lançamentos'!$H$6:$H$1505,12)) | N17: =IF($A17="","",SUM(B17:M17))
A18: TOTAL ENTRADAS | B18: =SUM(B8:B17) | C18: =SUM(C8:C17) | D18: =SUM(D8:D17) | E18: =SUM(E8:E17) | F18: =SUM(F8:F17) | G18: =SUM(G8:G17) | H18: =SUM(H8:H17) | I18: =SUM(I8:I17) | ... N18: =SUM(N8:N17)
A20: SAÍDAS
A21: =IF(Config!$F6="","",Config!$F6) | B21: =IF($A21="","",SUMIFS('Lançamentos'!$E$6:$E$1505,'Lançamentos'!$B$6:$B$1505,$A21,'Lançamentos'!$H$6:$H$1505,1)) | C21: =IF($A21="","",SUMIFS('Lançamentos'!$E$6:$E$1505,'Lançamentos'!$B$6:$B$1505,$A21,'Lançamentos'!$H$6:$H$1505,2)) | D21: =IF($A21="","",SUMIFS('Lançamentos'!$E$6:$E$1505,'Lançamentos'!$B$6:$B$1505,$A21,'Lançamentos'!$H$6:$H$1505,3)) | E21: =IF($A21="","",SUMIFS('Lançamentos'!$E$6:$E$1505,'Lançamentos'!$B$6:$B$1505,$A21,'Lançamentos'!$H$6:$H$1505,4)) | F21: =IF($A21="","",SUMIFS('Lançamentos'!$E$6:$E$1505,'Lançamentos'!$B$6:$B$1505,$A21,'Lançamentos'!$H$6:$H$1505,5)) | G21: =IF($A21="","",SUMIFS('Lançamentos'!$E$6:$E$1505,'Lançamentos'!$B$6:$B$1505,$A21,'Lançamentos'!$H$6:$H$1505,6)) | H21: =IF($A21="","",SUMIFS('Lançamentos'!$E$6:$E$1505,'Lançamentos'!$B$6:$B$1505,$A21,'Lançamentos'!$H$6:$H$1505,7)) | I21: =IF($A21="","",SUMIFS('Lançamentos'!$E$6:$E$1505,'Lançamentos'!$B$6:$B$1505,$A21,'Lançamentos'!$H$6:$H$1505,8)) | J21: =IF($A21="","",SUMIFS('Lançamentos'!$E$6:$E$1505,'Lançamentos'!$B$6:$B$1505,$A21,'Lançamentos'!$H$6:$H$1505,9)) | K21: =IF($A21="","",SUMIFS('Lançamentos'!$E$6:$E$1505,'Lançamentos'!$B$6:$B$1505,$A21,'Lançamentos'!$H$6:$H$1505,10)) | L21: =IF($A21="","",SUMIFS('Lançamentos'!$E$6:$E$1505,'Lançamentos'!$B$6:$B$1505,$A21,'Lançamentos'!$H$6:$H$1505,11)) | M21: =IF($A21="","",SUMIFS('Lançamentos'!$E$6:$E$1505,'Lançamentos'!$B$6:$B$1505,$A21,'Lançamentos'!$H$6:$H$1505,12)) | N21: =IF($A21="","",SUM(B21:M21))
A22: =IF(Config!$F7="","",Config!$F7) | B22: =IF($A22="","",SUMIFS('Lançamentos'!$E$6:$E$1505,'Lançamentos'!$B$6:$B$1505,$A22,'Lançamentos'!$H$6:$H$1505,1)) | C22: =IF($A22="","",SUMIFS('Lançamentos'!$E$6:$E$1505,'Lançamentos'!$B$6:$B$1505,$A22,'Lançamentos'!$H$6:$H$1505,2)) | D22: =IF($A22="","",SUMIFS('Lançamentos'!$E$6:$E$1505,'Lançamentos'!$B$6:$B$1505,$A22,'Lançamentos'!$H$6:$H$1505,3)) | E22: =IF($A22="","",SUMIFS('Lançamentos'!$E$6:$E$1505,'Lançamentos'!$B$6:$B$1505,$A22,'Lançamentos'!$H$6:$H$1505,4)) | F22: =IF($A22="","",SUMIFS('Lançamentos'!$E$6:$E$1505,'Lançamentos'!$B$6:$B$1505,$A22,'Lançamentos'!$H$6:$H$1505,5)) | G22: =IF($A22="","",SUMIFS('Lançamentos'!$E$6:$E$1505,'Lançamentos'!$B$6:$B$1505,$A22,'Lançamentos'!$H$6:$H$1505,6)) | H22: =IF($A22="","",SUMIFS('Lançamentos'!$E$6:$E$1505,'Lançamentos'!$B$6:$B$1505,$A22,'Lançamentos'!$H$6:$H$1505,7)) | I22: =IF($A22="","",SUMIFS('Lançamentos'!$E$6:$E$1505,'Lançamentos'!$B$6:$B$1505,$A22,'Lançamentos'!$H$6:$H$1505,8)) | J22: =IF($A22="","",SUMIFS('Lançamentos'!$E$6:$E$1505,'Lançamentos'!$B$6:$B$1505,$A22,'Lançamentos'!$H$6:$H$1505,9)) | K22: =IF($A22="","",SUMIFS('Lançamentos'!$E$6:$E$1505,'Lançamentos'!$B$6:$B$1505,$A22,'Lançamentos'!$H$6:$H$1505,10)) | L22: =IF($A22="","",SUMIFS('Lançamentos'!$E$6:$E$1505,'Lançamentos'!$B$6:$B$1505,$A22,'Lançamentos'!$H$6:$H$1505,11)) | M22: =IF($A22="","",SUMIFS('Lançamentos'!$E$6:$E$1505,'Lançamentos'!$B$6:$B$1505,$A22,'Lançamentos'!$H$6:$H$1505,12)) | N22: =IF($A22="","",SUM(B22:M22))
A23: =IF(Config!$F8="","",Config!$F8) | B23: =IF($A23="","",SUMIFS('Lançamentos'!$E$6:$E$1505,'Lançamentos'!$B$6:$B$1505,$A23,'Lançamentos'!$H$6:$H$1505,1)) | C23: =IF($A23="","",SUMIFS('Lançamentos'!$E$6:$E$1505,'Lançamentos'!$B$6:$B$1505,$A23,'Lançamentos'!$H$6:$H$1505,2)) | D23: =IF($A23="","",SUMIFS('Lançamentos'!$E$6:$E$1505,'Lançamentos'!$B$6:$B$1505,$A23,'Lançamentos'!$H$6:$H$1505,3)) | E23: =IF($A23="","",SUMIFS('Lançamentos'!$E$6:$E$1505,'Lançamentos'!$B$6:$B$1505,$A23,'Lançamentos'!$H$6:$H$1505,4)) | F23: =IF($A23="","",SUMIFS('Lançamentos'!$E$6:$E$1505,'Lançamentos'!$B$6:$B$1505,$A23,'Lançamentos'!$H$6:$H$1505,5)) | G23: =IF($A23="","",SUMIFS('Lançamentos'!$E$6:$E$1505,'Lançamentos'!$B$6:$B$1505,$A23,'Lançamentos'!$H$6:$H$1505,6)) | H23: =IF($A23="","",SUMIFS('Lançamentos'!$E$6:$E$1505,'Lançamentos'!$B$6:$B$1505,$A23,'Lançamentos'!$H$6:$H$1505,7)) | I23: =IF($A23="","",SUMIFS('Lançamentos'!$E$6:$E$1505,'Lançamentos'!$B$6:$B$1505,$A23,'Lançamentos'!$H$6:$H$1505,8)) | J23: =IF($A23="","",SUMIFS('Lançamentos'!$E$6:$E$1505,'Lançamentos'!$B$6:$B$1505,$A23,'Lançamentos'!$H$6:$H$1505,9)) | K23: =IF($A23="","",SUMIFS('Lançamentos'!$E$6:$E$1505,'Lançamentos'!$B$6:$B$1505,$A23,'Lançamentos'!$H$6:$H$1505,10)) | L23: =IF($A23="","",SUMIFS('Lançamentos'!$E$6:$E$1505,'Lançamentos'!$B$6:$B$1505,$A23,'Lançamentos'!$H$6:$H$1505,11)) | M23: =IF($A23="","",SUMIFS('Lançamentos'!$E$6:$E$1505,'Lançamentos'!$B$6:$B$1505,$A23,'Lançamentos'!$H$6:$H$1505,12)) | N23: =IF($A23="","",SUM(B23:M23))
A24: =IF(Config!$F9="","",Config!$F9) | B24: =IF($A24="","",SUMIFS('Lançamentos'!$E$6:$E$1505,'Lançamentos'!$B$6:$B$1505,$A24,'Lançamentos'!$H$6:$H$1505,1)) | C24: =IF($A24="","",SUMIFS('Lançamentos'!$E$6:$E$1505,'Lançamentos'!$B$6:$B$1505,$A24,'Lançamentos'!$H$6:$H$1505,2)) | D24: =IF($A24="","",SUMIFS('Lançamentos'!$E$6:$E$1505,'Lançamentos'!$B$6:$B$1505,$A24,'Lançamentos'!$H$6:$H$1505,3)) | E24: =IF($A24="","",SUMIFS('Lançamentos'!$E$6:$E$1505,'Lançamentos'!$B$6:$B$1505,$A24,'Lançamentos'!$H$6:$H$1505,4)) | F24: =IF($A24="","",SUMIFS('Lançamentos'!$E$6:$E$1505,'Lançamentos'!$B$6:$B$1505,$A24,'Lançamentos'!$H$6:$H$1505,5)) | G24: =IF($A24="","",SUMIFS('Lançamentos'!$E$6:$E$1505,'Lançamentos'!$B$6:$B$1505,$A24,'Lançamentos'!$H$6:$H$1505,6)) | H24: =IF($A24="","",SUMIFS('Lançamentos'!$E$6:$E$1505,'Lançamentos'!$B$6:$B$1505,$A24,'Lançamentos'!$H$6:$H$1505,7)) | I24: =IF($A24="","",SUMIFS('Lançamentos'!$E$6:$E$1505,'Lançamentos'!$B$6:$B$1505,$A24,'Lançamentos'!$H$6:$H$1505,8)) | J24: =IF($A24="","",SUMIFS('Lançamentos'!$E$6:$E$1505,'Lançamentos'!$B$6:$B$1505,$A24,'Lançamentos'!$H$6:$H$1505,9)) | K24: =IF($A24="","",SUMIFS('Lançamentos'!$E$6:$E$1505,'Lançamentos'!$B$6:$B$1505,$A24,'Lançamentos'!$H$6:$H$1505,10)) | L24: =IF($A24="","",SUMIFS('Lançamentos'!$E$6:$E$1505,'Lançamentos'!$B$6:$B$1505,$A24,'Lançamentos'!$H$6:$H$1505,11)) | M24: =IF($A24="","",SUMIFS('Lançamentos'!$E$6:$E$1505,'Lançamentos'!$B$6:$B$1505,$A24,'Lançamentos'!$H$6:$H$1505,12)) | N24: =IF($A24="","",SUM(B24:M24))
A25: =IF(Config!$F10="","",Config!$F10) | B25: =IF($A25="","",SUMIFS('Lançamentos'!$E$6:$E$1505,'Lançamentos'!$B$6:$B$1505,$A25,'Lançamentos'!$H$6:$H$1505,1)) | C25: =IF($A25="","",SUMIFS('Lançamentos'!$E$6:$E$1505,'Lançamentos'!$B$6:$B$1505,$A25,'Lançamentos'!$H$6:$H$1505,2)) | D25: =IF($A25="","",SUMIFS('Lançamentos'!$E$6:$E$1505,'Lançamentos'!$B$6:$B$1505,$A25,'Lançamentos'!$H$6:$H$1505,3)) | E25: =IF($A25="","",SUMIFS('Lançamentos'!$E$6:$E$1505,'Lançamentos'!$B$6:$B$1505,$A25,'Lançamentos'!$H$6:$H$1505,4)) | F25: =IF($A25="","",SUMIFS('Lançamentos'!$E$6:$E$1505,'Lançamentos'!$B$6:$B$1505,$A25,'Lançamentos'!$H$6:$H$1505,5)) | G25: =IF($A25="","",SUMIFS('Lançamentos'!$E$6:$E$1505,'Lançamentos'!$B$6:$B$1505,$A25,'Lançamentos'!$H$6:$H$1505,6)) | H25: =IF($A25="","",SUMIFS('Lançamentos'!$E$6:$E$1505,'Lançamentos'!$B$6:$B$1505,$A25,'Lançamentos'!$H$6:$H$1505,7)) | I25: =IF($A25="","",SUMIFS('Lançamentos'!$E$6:$E$1505,'Lançamentos'!$B$6:$B$1505,$A25,'Lançamentos'!$H$6:$H$1505,8)) | J25: =IF($A25="","",SUMIFS('Lançamentos'!$E$6:$E$1505,'Lançamentos'!$B$6:$B$1505,$A25,'Lançamentos'!$H$6:$H$1505,9)) | K25: =IF($A25="","",SUMIFS('Lançamentos'!$E$6:$E$1505,'Lançamentos'!$B$6:$B$1505,$A25,'Lançamentos'!$H$6:$H$1505,10)) | L25: =IF($A25="","",SUMIFS('Lançamentos'!$E$6:$E$1505,'Lançamentos'!$B$6:$B$1505,$A25,'Lançamentos'!$H$6:$H$1505,11)) | M25: =IF($A25="","",SUMIFS('Lançamentos'!$E$6:$E$1505,'Lançamentos'!$B$6:$B$1505,$A25,'Lançamentos'!$H$6:$H$1505,12)) | N25: =IF($A25="","",SUM(B25:M25))
A26: =IF(Config!$F11="","",Config!$F11) | B26: =IF($A26="","",SUMIFS('Lançamentos'!$E$6:$E$1505,'Lançamentos'!$B$6:$B$1505,$A26,'Lançamentos'!$H$6:$H$1505,1)) | C26: =IF($A26="","",SUMIFS('Lançamentos'!$E$6:$E$1505,'Lançamentos'!$B$6:$B$1505,$A26,'Lançamentos'!$H$6:$H$1505,2)) | D26: =IF($A26="","",SUMIFS('Lançamentos'!$E$6:$E$1505,'Lançamentos'!$B$6:$B$1505,$A26,'Lançamentos'!$H$6:$H$1505,3)) | E26: =IF($A26="","",SUMIFS('Lançamentos'!$E$6:$E$1505,'Lançamentos'!$B$6:$B$1505,$A26,'Lançamentos'!$H$6:$H$1505,4)) | F26: =IF($A26="","",SUMIFS('Lançamentos'!$E$6:$E$1505,'Lançamentos'!$B$6:$B$1505,$A26,'Lançamentos'!$H$6:$H$1505,5)) | G26: =IF($A26="","",SUMIFS('Lançamentos'!$E$6:$E$1505,'Lançamentos'!$B$6:$B$1505,$A26,'Lançamentos'!$H$6:$H$1505,6)) | H26: =IF($A26="","",SUMIFS('Lançamentos'!$E$6:$E$1505,'Lançamentos'!$B$6:$B$1505,$A26,'Lançamentos'!$H$6:$H$1505,7)) | I26: =IF($A26="","",SUMIFS('Lançamentos'!$E$6:$E$1505,'Lançamentos'!$B$6:$B$1505,$A26,'Lançamentos'!$H$6:$H$1505,8)) | J26: =IF($A26="","",SUMIFS('Lançamentos'!$E$6:$E$1505,'Lançamentos'!$B$6:$B$1505,$A26,'Lançamentos'!$H$6:$H$1505,9)) | K26: =IF($A26="","",SUMIFS('Lançamentos'!$E$6:$E$1505,'Lançamentos'!$B$6:$B$1505,$A26,'Lançamentos'!$H$6:$H$1505,10)) | L26: =IF($A26="","",SUMIFS('Lançamentos'!$E$6:$E$1505,'Lançamentos'!$B$6:$B$1505,$A26,'Lançamentos'!$H$6:$H$1505,11)) | M26: =IF($A26="","",SUMIFS('Lançamentos'!$E$6:$E$1505,'Lançamentos'!$B$6:$B$1505,$A26,'Lançamentos'!$H$6:$H$1505,12)) | N26: =IF($A26="","",SUM(B26:M26))
A27: =IF(Config!$F12="","",Config!$F12) | B27: =IF($A27="","",SUMIFS('Lançamentos'!$E$6:$E$1505,'Lançamentos'!$B$6:$B$1505,$A27,'Lançamentos'!$H$6:$H$1505,1)) | C27: =IF($A27="","",SUMIFS('Lançamentos'!$E$6:$E$1505,'Lançamentos'!$B$6:$B$1505,$A27,'Lançamentos'!$H$6:$H$1505,2)) | D27: =IF($A27="","",SUMIFS('Lançamentos'!$E$6:$E$1505,'Lançamentos'!$B$6:$B$1505,$A27,'Lançamentos'!$H$6:$H$1505,3)) | E27: =IF($A27="","",SUMIFS('Lançamentos'!$E$6:$E$1505,'Lançamentos'!$B$6:$B$1505,$A27,'Lançamentos'!$H$6:$H$1505,4)) | F27: =IF($A27="","",SUMIFS('Lançamentos'!$E$6:$E$1505,'Lançamentos'!$B$6:$B$1505,$A27,'Lançamentos'!$H$6:$H$1505,5)) | G27: =IF($A27="","",SUMIFS('Lançamentos'!$E$6:$E$1505,'Lançamentos'!$B$6:$B$1505,$A27,'Lançamentos'!$H$6:$H$1505,6)) | H27: =IF($A27="","",SUMIFS('Lançamentos'!$E$6:$E$1505,'Lançamentos'!$B$6:$B$1505,$A27,'Lançamentos'!$H$6:$H$1505,7)) | I27: =IF($A27="","",SUMIFS('Lançamentos'!$E$6:$E$1505,'Lançamentos'!$B$6:$B$1505,$A27,'Lançamentos'!$H$6:$H$1505,8)) | J27: =IF($A27="","",SUMIFS('Lançamentos'!$E$6:$E$1505,'Lançamentos'!$B$6:$B$1505,$A27,'Lançamentos'!$H$6:$H$1505,9)) | K27: =IF($A27="","",SUMIFS('Lançamentos'!$E$6:$E$1505,'Lançamentos'!$B$6:$B$1505,$A27,'Lançamentos'!$H$6:$H$1505,10)) | L27: =IF($A27="","",SUMIFS('Lançamentos'!$E$6:$E$1505,'Lançamentos'!$B$6:$B$1505,$A27,'Lançamentos'!$H$6:$H$1505,11)) | M27: =IF($A27="","",SUMIFS('Lançamentos'!$E$6:$E$1505,'Lançamentos'!$B$6:$B$1505,$A27,'Lançamentos'!$H$6:$H$1505,12)) | N27: =IF($A27="","",SUM(B27:M27))
A28: =IF(Config!$F13="","",Config!$F13) | B28: =IF($A28="","",SUMIFS('Lançamentos'!$E$6:$E$1505,'Lançamentos'!$B$6:$B$1505,$A28,'Lançamentos'!$H$6:$H$1505,1)) | C28: =IF($A28="","",SUMIFS('Lançamentos'!$E$6:$E$1505,'Lançamentos'!$B$6:$B$1505,$A28,'Lançamentos'!$H$6:$H$1505,2)) | D28: =IF($A28="","",SUMIFS('Lançamentos'!$E$6:$E$1505,'Lançamentos'!$B$6:$B$1505,$A28,'Lançamentos'!$H$6:$H$1505,3)) | E28: =IF($A28="","",SUMIFS('Lançamentos'!$E$6:$E$1505,'Lançamentos'!$B$6:$B$1505,$A28,'Lançamentos'!$H$6:$H$1505,4)) | F28: =IF($A28="","",SUMIFS('Lançamentos'!$E$6:$E$1505,'Lançamentos'!$B$6:$B$1505,$A28,'Lançamentos'!$H$6:$H$1505,5)) | G28: =IF($A28="","",SUMIFS('Lançamentos'!$E$6:$E$1505,'Lançamentos'!$B$6:$B$1505,$A28,'Lançamentos'!$H$6:$H$1505,6)) | H28: =IF($A28="","",SUMIFS('Lançamentos'!$E$6:$E$1505,'Lançamentos'!$B$6:$B$1505,$A28,'Lançamentos'!$H$6:$H$1505,7)) | I28: =IF($A28="","",SUMIFS('Lançamentos'!$E$6:$E$1505,'Lançamentos'!$B$6:$B$1505,$A28,'Lançamentos'!$H$6:$H$1505,8)) | J28: =IF($A28="","",SUMIFS('Lançamentos'!$E$6:$E$1505,'Lançamentos'!$B$6:$B$1505,$A28,'Lançamentos'!$H$6:$H$1505,9)) | K28: =IF($A28="","",SUMIFS('Lançamentos'!$E$6:$E$1505,'Lançamentos'!$B$6:$B$1505,$A28,'Lançamentos'!$H$6:$H$1505,10)) | L28: =IF($A28="","",SUMIFS('Lançamentos'!$E$6:$E$1505,'Lançamentos'!$B$6:$B$1505,$A28,'Lançamentos'!$H$6:$H$1505,11)) | M28: =IF($A28="","",SUMIFS('Lançamentos'!$E$6:$E$1505,'Lançamentos'!$B$6:$B$1505,$A28,'Lançamentos'!$H$6:$H$1505,12)) | N28: =IF($A28="","",SUM(B28:M28))
A29: =IF(Config!$F14="","",Config!$F14) | B29: =IF($A29="","",SUMIFS('Lançamentos'!$E$6:$E$1505,'Lançamentos'!$B$6:$B$1505,$A29,'Lançamentos'!$H$6:$H$1505,1)) | C29: =IF($A29="","",SUMIFS('Lançamentos'!$E$6:$E$1505,'Lançamentos'!$B$6:$B$1505,$A29,'Lançamentos'!$H$6:$H$1505,2)) | D29: =IF($A29="","",SUMIFS('Lançamentos'!$E$6:$E$1505,'Lançamentos'!$B$6:$B$1505,$A29,'Lançamentos'!$H$6:$H$1505,3)) | E29: =IF($A29="","",SUMIFS('Lançamentos'!$E$6:$E$1505,'Lançamentos'!$B$6:$B$1505,$A29,'Lançamentos'!$H$6:$H$1505,4)) | F29: =IF($A29="","",SUMIFS('Lançamentos'!$E$6:$E$1505,'Lançamentos'!$B$6:$B$1505,$A29,'Lançamentos'!$H$6:$H$1505,5)) | G29: =IF($A29="","",SUMIFS('Lançamentos'!$E$6:$E$1505,'Lançamentos'!$B$6:$B$1505,$A29,'Lançamentos'!$H$6:$H$1505,6)) | H29: =IF($A29="","",SUMIFS('Lançamentos'!$E$6:$E$1505,'Lançamentos'!$B$6:$B$1505,$A29,'Lançamentos'!$H$6:$H$1505,7)) | I29: =IF($A29="","",SUMIFS('Lançamentos'!$E$6:$E$1505,'Lançamentos'!$B$6:$B$1505,$A29,'Lançamentos'!$H$6:$H$1505,8)) | J29: =IF($A29="","",SUMIFS('Lançamentos'!$E$6:$E$1505,'Lançamentos'!$B$6:$B$1505,$A29,'Lançamentos'!$H$6:$H$1505,9)) | K29: =IF($A29="","",SUMIFS('Lançamentos'!$E$6:$E$1505,'Lançamentos'!$B$6:$B$1505,$A29,'Lançamentos'!$H$6:$H$1505,10)) | L29: =IF($A29="","",SUMIFS('Lançamentos'!$E$6:$E$1505,'Lançamentos'!$B$6:$B$1505,$A29,'Lançamentos'!$H$6:$H$1505,11)) | M29: =IF($A29="","",SUMIFS('Lançamentos'!$E$6:$E$1505,'Lançamentos'!$B$6:$B$1505,$A29,'Lançamentos'!$H$6:$H$1505,12)) | N29: =IF($A29="","",SUM(B29:M29))
A30: =IF(Config!$F15="","",Config!$F15) | B30: =IF($A30="","",SUMIFS('Lançamentos'!$E$6:$E$1505,'Lançamentos'!$B$6:$B$1505,$A30,'Lançamentos'!$H$6:$H$1505,1)) | C30: =IF($A30="","",SUMIFS('Lançamentos'!$E$6:$E$1505,'Lançamentos'!$B$6:$B$1505,$A30,'Lançamentos'!$H$6:$H$1505,2)) | D30: =IF($A30="","",SUMIFS('Lançamentos'!$E$6:$E$1505,'Lançamentos'!$B$6:$B$1505,$A30,'Lançamentos'!$H$6:$H$1505,3)) | E30: =IF($A30="","",SUMIFS('Lançamentos'!$E$6:$E$1505,'Lançamentos'!$B$6:$B$1505,$A30,'Lançamentos'!$H$6:$H$1505,4)) | F30: =IF($A30="","",SUMIFS('Lançamentos'!$E$6:$E$1505,'Lançamentos'!$B$6:$B$1505,$A30,'Lançamentos'!$H$6:$H$1505,5)) | G30: =IF($A30="","",SUMIFS('Lançamentos'!$E$6:$E$1505,'Lançamentos'!$B$6:$B$1505,$A30,'Lançamentos'!$H$6:$H$1505,6)) | H30: =IF($A30="","",SUMIFS('Lançamentos'!$E$6:$E$1505,'Lançamentos'!$B$6:$B$1505,$A30,'Lançamentos'!$H$6:$H$1505,7)) | I30: =IF($A30="","",SUMIFS('Lançamentos'!$E$6:$E$1505,'Lançamentos'!$B$6:$B$1505,$A30,'Lançamentos'!$H$6:$H$1505,8)) | J30: =IF($A30="","",SUMIFS('Lançamentos'!$E$6:$E$1505,'Lançamentos'!$B$6:$B$1505,$A30,'Lançamentos'!$H$6:$H$1505,9)) | K30: =IF($A30="","",SUMIFS('Lançamentos'!$E$6:$E$1505,'Lançamentos'!$B$6:$B$1505,$A30,'Lançamentos'!$H$6:$H$1505,10)) | L30: =IF($A30="","",SUMIFS('Lançamentos'!$E$6:$E$1505,'Lançamentos'!$B$6:$B$1505,$A30,'Lançamentos'!$H$6:$H$1505,11)) | M30: =IF($A30="","",SUMIFS('Lançamentos'!$E$6:$E$1505,'Lançamentos'!$B$6:$B$1505,$A30,'Lançamentos'!$H$6:$H$1505,12)) | N30: =IF($A30="","",SUM(B30:M30))
A31: =IF(Config!$F16="","",Config!$F16) | B31: =IF($A31="","",SUMIFS('Lançamentos'!$E$6:$E$1505,'Lançamentos'!$B$6:$B$1505,$A31,'Lançamentos'!$H$6:$H$1505,1)) | C31: =IF($A31="","",SUMIFS('Lançamentos'!$E$6:$E$1505,'Lançamentos'!$B$6:$B$1505,$A31,'Lançamentos'!$H$6:$H$1505,2)) | D31: =IF($A31="","",SUMIFS('Lançamentos'!$E$6:$E$1505,'Lançamentos'!$B$6:$B$1505,$A31,'Lançamentos'!$H$6:$H$1505,3)) | E31: =IF($A31="","",SUMIFS('Lançamentos'!$E$6:$E$1505,'Lançamentos'!$B$6:$B$1505,$A31,'Lançamentos'!$H$6:$H$1505,4)) | F31: =IF($A31="","",SUMIFS('Lançamentos'!$E$6:$E$1505,'Lançamentos'!$B$6:$B$1505,$A31,'Lançamentos'!$H$6:$H$1505,5)) | G31: =IF($A31="","",SUMIFS('Lançamentos'!$E$6:$E$1505,'Lançamentos'!$B$6:$B$1505,$A31,'Lançamentos'!$H$6:$H$1505,6)) | H31: =IF($A31="","",SUMIFS('Lançamentos'!$E$6:$E$1505,'Lançamentos'!$B$6:$B$1505,$A31,'Lançamentos'!$H$6:$H$1505,7)) | I31: =IF($A31="","",SUMIFS('Lançamentos'!$E$6:$E$1505,'Lançamentos'!$B$6:$B$1505,$A31,'Lançamentos'!$H$6:$H$1505,8)) | J31: =IF($A31="","",SUMIFS('Lançamentos'!$E$6:$E$1505,'Lançamentos'!$B$6:$B$1505,$A31,'Lançamentos'!$H$6:$H$1505,9)) | K31: =IF($A31="","",SUMIFS('Lançamentos'!$E$6:$E$1505,'Lançamentos'!$B$6:$B$1505,$A31,'Lançamentos'!$H$6:$H$1505,10)) | L31: =IF($A31="","",SUMIFS('Lançamentos'!$E$6:$E$1505,'Lançamentos'!$B$6:$B$1505,$A31,'Lançamentos'!$H$6:$H$1505,11)) | M31: =IF($A31="","",SUMIFS('Lançamentos'!$E$6:$E$1505,'Lançamentos'!$B$6:$B$1505,$A31,'Lançamentos'!$H$6:$H$1505,12)) | N31: =IF($A31="","",SUM(B31:M31))
A32: =IF(Config!$F17="","",Config!$F17) | B32: =IF($A32="","",SUMIFS('Lançamentos'!$E$6:$E$1505,'Lançamentos'!$B$6:$B$1505,$A32,'Lançamentos'!$H$6:$H$1505,1)) | C32: =IF($A32="","",SUMIFS('Lançamentos'!$E$6:$E$1505,'Lançamentos'!$B$6:$B$1505,$A32,'Lançamentos'!$H$6:$H$1505,2)) | D32: =IF($A32="","",SUMIFS('Lançamentos'!$E$6:$E$1505,'Lançamentos'!$B$6:$B$1505,$A32,'Lançamentos'!$H$6:$H$1505,3)) | E32: =IF($A32="","",SUMIFS('Lançamentos'!$E$6:$E$1505,'Lançamentos'!$B$6:$B$1505,$A32,'Lançamentos'!$H$6:$H$1505,4)) | F32: =IF($A32="","",SUMIFS('Lançamentos'!$E$6:$E$1505,'Lançamentos'!$B$6:$B$1505,$A32,'Lançamentos'!$H$6:$H$1505,5)) | G32: =IF($A32="","",SUMIFS('Lançamentos'!$E$6:$E$1505,'Lançamentos'!$B$6:$B$1505,$A32,'Lançamentos'!$H$6:$H$1505,6)) | H32: =IF($A32="","",SUMIFS('Lançamentos'!$E$6:$E$1505,'Lançamentos'!$B$6:$B$1505,$A32,'Lançamentos'!$H$6:$H$1505,7)) | I32: =IF($A32="","",SUMIFS('Lançamentos'!$E$6:$E$1505,'Lançamentos'!$B$6:$B$1505,$A32,'Lançamentos'!$H$6:$H$1505,8)) | J32: =IF($A32="","",SUMIFS('Lançamentos'!$E$6:$E$1505,'Lançamentos'!$B$6:$B$1505,$A32,'Lançamentos'!$H$6:$H$1505,9)) | K32: =IF($A32="","",SUMIFS('Lançamentos'!$E$6:$E$1505,'Lançamentos'!$B$6:$B$1505,$A32,'Lançamentos'!$H$6:$H$1505,10)) | L32: =IF($A32="","",SUMIFS('Lançamentos'!$E$6:$E$1505,'Lançamentos'!$B$6:$B$1505,$A32,'Lançamentos'!$H$6:$H$1505,11)) | M32: =IF($A32="","",SUMIFS('Lançamentos'!$E$6:$E$1505,'Lançamentos'!$B$6:$B$1505,$A32,'Lançamentos'!$H$6:$H$1505,12)) | N32: =IF($A32="","",SUM(B32:M32))
... A40: =IF(Config!$F25="","",Config!$F25) | B40: =IF($A40="","",SUMIFS('Lançamentos'!$E$6:$E$1505,'Lançamentos'!$B$6:$B$1505,$A40,'Lançamentos'!$H$6:$H$1505,1)) | C40: =IF($A40="","",SUMIFS('Lançamentos'!$E$6:$E$1505,'Lançamentos'!$B$6:$B$1505,$A40,'Lançamentos'!$H$6:$H$1505,2)) | D40: =IF($A40="","",SUMIFS('Lançamentos'!$E$6:$E$1505,'Lançamentos'!$B$6:$B$1505,$A40,'Lançamentos'!$H$6:$H$1505,3)) | E40: =IF($A40="","",SUMIFS('Lançamentos'!$E$6:$E$1505,'Lançamentos'!$B$6:$B$1505,$A40,'Lançamentos'!$H$6:$H$1505,4)) | F40: =IF($A40="","",SUMIFS('Lançamentos'!$E$6:$E$1505,'Lançamentos'!$B$6:$B$1505,$A40,'Lançamentos'!$H$6:$H$1505,5)) | G40: =IF($A40="","",SUMIFS('Lançamentos'!$E$6:$E$1505,'Lançamentos'!$B$6:$B$1505,$A40,'Lançamentos'!$H$6:$H$1505,6)) | H40: =IF($A40="","",SUMIFS('Lançamentos'!$E$6:$E$1505,'Lançamentos'!$B$6:$B$1505,$A40,'Lançamentos'!$H$6:$H$1505,7)) | I40: =IF($A40="","",SUMIFS('Lançamentos'!$E$6:$E$1505,'Lançamentos'!$B$6:$B$1505,$A40,'Lançamentos'!$H$6:$H$1505,8)) | J40: =IF($A40="","",SUMIFS('Lançamentos'!$E$6:$E$1505,'Lançamentos'!$B$6:$B$1505,$A40,'Lançamentos'!$H$6:$H$1505,9)) | K40: =IF($A40="","",SUMIFS('Lançamentos'!$E$6:$E$1505,'Lançamentos'!$B$6:$B$1505,$A40,'Lançamentos'!$H$6:$H$1505,10)) | L40: =IF($A40="","",SUMIFS('Lançamentos'!$E$6:$E$1505,'Lançamentos'!$B$6:$B$1505,$A40,'Lançamentos'!$H$6:$H$1505,11)) | M40: =IF($A40="","",SUMIFS('Lançamentos'!$E$6:$E$1505,'Lançamentos'!$B$6:$B$1505,$A40,'Lançamentos'!$H$6:$H$1505,12)) | N40: =IF($A40="","",SUM(B40:M40))
A41: TOTAL SAÍDAS | B41: =SUM(B21:B40) | C41: =SUM(C21:C40) | D41: =SUM(D21:D40) | E41: =SUM(E21:E40) | F41: =SUM(F21:F40) | G41: =SUM(G21:G40) | H41: =SUM(H21:H40) | I41: =SUM(I21:I40) | ... N41: =SUM(N21:N40)
A43: RESULTADO
A44: Saldo do mês (entradas − saídas) | B44: =B18-B41 | C44: =C18-C41 | D44: =D18-D41 | E44: =E18-E41 | F44: =F18-F41 | G44: =G18-G41 | H44: =H18-H41 | I44: =I18-I41 | ... N44: =N18-N41
A45: Saldo inicial do mês | B45: =Config!$B$7 | C45: =B46 | D45: =C46 | E45: =D46 | F45: =E46 | G45: =F46 | H45: =G46 | I45: =H46 | J45: =I46 | ... M45: =L46 | N45: =B45
A46: Saldo acumulado (final do mês) | B46: =B45+B44 | C46: =C45+C44 | D46: =D45+D44 | E46: =E45+E44 | F46: =F45+F44 | G46: =G45+G44 | H46: =H45+H44 | I46: =I45+I44 | ... M46: =M45+M44 | N46: =M46

Sheet Previsto x Realizado
A1: Previsto x Realizado
A2: Comparação anual por categoria
A3: Legenda: | B3: Preencher | C3: Cálculo automático (protegido)
A5: Categoria | B5: Tipo | C5: Previsto (12 meses) | D5: Realizado (12 meses) | E5: Diferença (realizado − previsto) | F5: % realizado | G5: Situação
A6: ='Previsto'!A8 | B6: =IF(A6="","","Entrada") | C6: =IF(A6="","",N('Previsto'!N8)) | D6: =IF(A6="","",N('Fluxo Realizado'!N8)) | E6: =IF(A6="","",D6-C6) | F6: =IF(A6="","",IFERROR(D6/C6,0)) | G6: =IF(A6="","",IF(AND(C6=0,D6=0),"Sem valores",IF(D6>=C6,"No previsto ou acima","Abaixo do previsto")))
A7: ='Previsto'!A9 | B7: =IF(A7="","","Entrada") | C7: =IF(A7="","",N('Previsto'!N9)) | D7: =IF(A7="","",N('Fluxo Realizado'!N9)) | E7: =IF(A7="","",D7-C7) | F7: =IF(A7="","",IFERROR(D7/C7,0)) | G7: =IF(A7="","",IF(AND(C7=0,D7=0),"Sem valores",IF(D7>=C7,"No previsto ou acima","Abaixo do previsto")))
A8: ='Previsto'!A10 | B8: =IF(A8="","","Entrada") | C8: =IF(A8="","",N('Previsto'!N10)) | D8: =IF(A8="","",N('Fluxo Realizado'!N10)) | E8: =IF(A8="","",D8-C8) | F8: =IF(A8="","",IFERROR(D8/C8,0)) | G8: =IF(A8="","",IF(AND(C8=0,D8=0),"Sem valores",IF(D8>=C8,"No previsto ou acima","Abaixo do previsto")))
A9: ='Previsto'!A11 | B9: =IF(A9="","","Entrada") | C9: =IF(A9="","",N('Previsto'!N11)) | D9: =IF(A9="","",N('Fluxo Realizado'!N11)) | E9: =IF(A9="","",D9-C9) | F9: =IF(A9="","",IFERROR(D9/C9,0)) | G9: =IF(A9="","",IF(AND(C9=0,D9=0),"Sem valores",IF(D9>=C9,"No previsto ou acima","Abaixo do previsto")))
A10: ='Previsto'!A12 | B10: =IF(A10="","","Entrada") | C10: =IF(A10="","",N('Previsto'!N12)) | D10: =IF(A10="","",N('Fluxo Realizado'!N12)) | E10: =IF(A10="","",D10-C10) | F10: =IF(A10="","",IFERROR(D10/C10,0)) | G10: =IF(A10="","",IF(AND(C10=0,D10=0),"Sem valores",IF(D10>=C10,"No previsto ou acima","Abaixo do previsto")))
A11: ='Previsto'!A13 | B11: =IF(A11="","","Entrada") | C11: =IF(A11="","",N('Previsto'!N13)) | D11: =IF(A11="","",N('Fluxo Realizado'!N13)) | E11: =IF(A11="","",D11-C11) | F11: =IF(A11="","",IFERROR(D11/C11,0)) | G11: =IF(A11="","",IF(AND(C11=0,D11=0),"Sem valores",IF(D11>=C11,"No previsto ou acima","Abaixo do previsto")))
A12: ='Previsto'!A14 | B12: =IF(A12="","","Entrada") | C12: =IF(A12="","",N('Previsto'!N14)) | D12: =IF(A12="","",N('Fluxo Realizado'!N14)) | E12: =IF(A12="","",D12-C12) | F12: =IF(A12="","",IFERROR(D12/C12,0)) | G12: =IF(A12="","",IF(AND(C12=0,D12=0),"Sem valores",IF(D12>=C12,"No previsto ou acima","Abaixo do previsto")))
A13: ='Previsto'!A15 | B13: =IF(A13="","","Entrada") | C13: =IF(A13="","",N('Previsto'!N15)) | D13: =IF(A13="","",N('Fluxo Realizado'!N15)) | E13: =IF(A13="","",D13-C13) | F13: =IF(A13="","",IFERROR(D13/C13,0)) | G13: =IF(A13="","",IF(AND(C13=0,D13=0),"Sem valores",IF(D13>=C13,"No previsto ou acima","Abaixo do previsto")))
A14: ='Previsto'!A16 | B14: =IF(A14="","","Entrada") | C14: =IF(A14="","",N('Previsto'!N16)) | D14: =IF(A14="","",N('Fluxo Realizado'!N16)) | E14: =IF(A14="","",D14-C14) | F14: =IF(A14="","",IFERROR(D14/C14,0)) | G14: =IF(A14="","",IF(AND(C14=0,D14=0),"Sem valores",IF(D14>=C14,"No previsto ou acima","Abaixo do previsto")))
A15: ='Previsto'!A17 | B15: =IF(A15="","","Entrada") | C15: =IF(A15="","",N('Previsto'!N17)) | D15: =IF(A15="","",N('Fluxo Realizado'!N17)) | E15: =IF(A15="","",D15-C15) | F15: =IF(A15="","",IFERROR(D15/C15,0)) | G15: =IF(A15="","",IF(AND(C15=0,D15=0),"Sem valores",IF(D15>=C15,"No previsto ou acima","Abaixo do previsto")))
A16: TOTAL ENTRADAS | C16: =SUM(C6:C15) | D16: =SUM(D6:D15) | E16: =SUM(E6:E15) | F16: =IFERROR(D16/C16,0)
A18: ='Previsto'!A21 | B18: =IF(A18="","","Saída") | C18: =IF(A18="","",N('Previsto'!N21)) | D18: =IF(A18="","",N('Fluxo Realizado'!N21)) | E18: =IF(A18="","",D18-C18) | F18: =IF(A18="","",IFERROR(D18/C18,0)) | G18: =IF(A18="","",IF(AND(C18=0,D18=0),"Sem valores",IF(D18<=C18,"Dentro do previsto","Acima do previsto")))
A19: ='Previsto'!A22 | B19: =IF(A19="","","Saída") | C19: =IF(A19="","",N('Previsto'!N22)) | D19: =IF(A19="","",N('Fluxo Realizado'!N22)) | E19: =IF(A19="","",D19-C19) | F19: =IF(A19="","",IFERROR(D19/C19,0)) | G19: =IF(A19="","",IF(AND(C19=0,D19=0),"Sem valores",IF(D19<=C19,"Dentro do previsto","Acima do previsto")))
A20: ='Previsto'!A23 | B20: =IF(A20="","","Saída") | C20: =IF(A20="","",N('Previsto'!N23)) | D20: =IF(A20="","",N('Fluxo Realizado'!N23)) | E20: =IF(A20="","",D20-C20) | F20: =IF(A20="","",IFERROR(D20/C20,0)) | G20: =IF(A20="","",IF(AND(C20=0,D20=0),"Sem valores",IF(D20<=C20,"Dentro do previsto","Acima do previsto")))
A21: ='Previsto'!A24 | B21: =IF(A21="","","Saída") | C21: =IF(A21="","",N('Previsto'!N24)) | D21: =IF(A21="","",N('Fluxo Realizado'!N24)) | E21: =IF(A21="","",D21-C21) | F21: =IF(A21="","",IFERROR(D21/C21,0)) | G21: =IF(A21="","",IF(AND(C21=0,D21=0),"Sem valores",IF(D21<=C21,"Dentro do previsto","Acima do previsto")))
A22: ='Previsto'!A25 | B22: =IF(A22="","","Saída") | C22: =IF(A22="","",N('Previsto'!N25)) | D22: =IF(A22="","",N('Fluxo Realizado'!N25)) | E22: =IF(A22="","",D22-C22) | F22: =IF(A22="","",IFERROR(D22/C22,0)) | G22: =IF(A22="","",IF(AND(C22=0,D22=0),"Sem valores",IF(D22<=C22,"Dentro do previsto","Acima do previsto")))
A23: ='Previsto'!A26 | B23: =IF(A23="","","Saída") | C23: =IF(A23="","",N('Previsto'!N26)) | D23: =IF(A23="","",N('Fluxo Realizado'!N26)) | E23: =IF(A23="","",D23-C23) | F23: =IF(A23="","",IFERROR(D23/C23,0)) | G23: =IF(A23="","",IF(AND(C23=0,D23=0),"Sem valores",IF(D23<=C23,"Dentro do previsto","Acima do previsto")))
